Workbook
Name г._Москва___город_федерального_значения: #REF!
Name А1: #REF!

Sheet cancer_by_region_edit
A1: region | B1: region_english | C1: squares code | D1: male_abs_num | E1: female_abs_num | F1: male_population_0-14 | G1: female_population_0-14 | H1: male_per_100k | I1: female_per_100k | J1: total_per_100k | K1: total_death_risk_group
A2: Белгородская область | B2: Belgorod Oblast | C2: БЕЛ | D2: 22 | E2: 17 | F2: =SUMIF(population_edit!A$2:A$1276, A2, population_edit!C$2:C$1276) -> 121398 | G2: =SUMIF(population_edit!A$2:A$1274, A2, population_edit!D$2:D$1276) -> 114774 | H2: =(D2/F2)*100000 -> 18.12221 | I2: =(E2/G2)*100000 -> 14.811717 | J2: =IFERROR( (D2 + E2) / (F2 + G2) * 100000, "" ) -> 16.513389 | K2: =IF(J2 <= PERCENTILE(J$2:J$86, 0.33), "Низкий", IF(J2 <= PERCENTILE(J$2:J$86, 0.67), "Средний", "Высокий")) -> Высокий
A3: Брянская область | B3: Bryansk Oblast | C3: БРЯ | D3: 18 | E3: 13 | F3: =SUMIF(population_edit!A$2:A$1276, A3, population_edit!C$2:C$1276) -> 94158 | G3: =SUMIF(population_edit!A$2:A$1274, A3, population_edit!D$2:D$1276) -> 89345 | H3: =(D3/F3)*100000 -> 19.116804 | I3: =(E3/G3)*100000 -> 14.550339 | J3: =IFERROR( (D3 + E3) / (F3 + G3) * 100000, "" ) -> 16.893457 | K3: =IF(J3 <= PERCENTILE(J$2:J$86, 0.33), "Низкий", IF(J3 <= PERCENTILE(J$2:J$86, 0.67), "Средний", "Высокий")) -> Высокий
A4: Владимирская область | B4: Vladimir Oblast | C4: ВЛД | D4: 19 | E4: 9 | F4: =SUMIF(population_edit!A$2:A$1276, A4, population_edit!C$2:C$1276) -> 103446 | G4: =SUMIF(population_edit!A$2:A$1274, A4, population_edit!D$2:D$1276) -> 97637 | H4: =(D4/F4)*100000 -> 18.367071 | I4: =(E4/G4)*100000 -> 9.217817 | J4: =IFERROR( (D4 + E4) / (F4 + G4) * 100000, "" ) -> 13.924598 | K4: =IF(J4 <= PERCENTILE(J$2:J$86, 0.33), "Низкий", IF(J4 <= PERCENTILE(J$2:J$86, 0.67), "Средний", "Высокий")) -> Высокий
A5: Воронежская область | B5: Voronezh Oblast | C5: ВРЖ | D5: 7 | E5: 8 | F5: =SUMIF(population_edit!A$2:A$1276, A5, population_edit!C$2:C$1276) -> 176987 | G5: =SUMIF(population_edit!A$2:A$1274, A5, population_edit!D$2:D$1276) -> 167519 | H5: =(D5/F5)*100000 -> 3.9550927 | I5: =(E5/G5)*100000 -> 4.7755777 | J5: =IFERROR( (D5 + E5) / (F5 + G5) * 100000, "" ) -> 4.3540606 | K5: =IF(J5 <= PERCENTILE(J$2:J$86, 0.33), "Низкий", IF(J5 <= PERCENTILE(J$2:J$86, 0.67), "Средний", "Высокий")) -> Низкий
A6: Ивановская область | B6: Ivanovo Oblast | C6: ИВА | D6: 4 | E6: 7 | F6: =SUMIF(population_edit!A$2:A$1276, A6, population_edit!C$2:C$1276) -> 71508 | G6: =SUMIF(population_edit!A$2:A$1274, A6, population_edit!D$2:D$1276) -> 66340 | H6: =(D6/F6)*100000 -> 5.5937797 | I6: =(E6/G6)*100000 -> 10.551703 | J6: =IFERROR( (D6 + E6) / (F6 + G6) * 100000, "" ) -> 7.9798038 | K6: =IF(J6 <= PERCENTILE(J$2:J$86, 0.33), "Низкий", IF(J6 <= PERCENTILE(J$2:J$86, 0.67), "Средний", "Высокий")) -> Низкий
A7: Тверская область | B7: Tver Oblast | C7: ТВР | D7: 5 | E7: 10 | F7: =SUMIF(population_edit!A$2:A$1276, A7, population_edit!C$2:C$1276) -> 96124 | G7: =SUMIF(population_edit!A$2:A$1274, A7, population_edit!D$2:D$1276) -> 92030 | H7: =(D7/F7)*100000 -> 5.2016146 | I7: =(E7/G7)*100000 -> 10.866022 | J7: =IFERROR( (D7 + E7) / (F7 + G7) * 100000, "" ) -> 7.972193 | K7: =IF(J7 <= PERCENTILE(J$2:J$86, 0.33), "Низкий", IF(J7 <= PERCENTILE(J$2:J$86, 0.67), "Средний", "Высокий")) -> Низкий
A8: Калужская область | B8: Kaluga Oblast | C8: КЛУ | D8: 6 | E8: 8 | F8: =SUMIF(population_edit!A$2:A$1276, A8, population_edit!C$2:C$1276) -> 86603 | G8: =SUMIF(population_edit!A$2:A$1274, A8, population_edit!D$2:D$1276) -> 82533 | H8: =(D8/F8)*100000 -> 6.9281665 | I8: =(E8/G8)*100000 -> 9.6930925 | J8: =IFERROR( (D8 + E8) / (F8 + G8) * 100000, "" ) -> 8.2773626 | K8: =IF(J8 <= PERCENTILE(J$2:J$86, 0.33), "Низкий", IF(J8 <= PERCENTILE(J$2:J$86, 0.67), "Средний", "Высокий")) -> Низкий
A9: Костромская область | B9: Kostroma Oblast | C9: КОС | D9: 5 | E9: 1 | F9: =SUMIF(population_edit!A$2:A$1276, A9, population_edit!C$2:C$1276) -> 50857 | G9: =SUMIF(population_edit!A$2:A$1274, A9, population_edit!D$2:D$1276) -> 48582 | H9: =(D9/F9)*100000 -> 9.8314883 | I9: =(E9/G9)*100000 -> 2.0583755 | J9: =IFERROR( (D9 + E9) / (F9 + G9) * 100000, "" ) -> 6.0338499 | K9: =IF(J9 <= PERCENTILE(J$2:J$86, 0.33), "Низкий", IF(J9 <= PERCENTILE(J$2:J$86, 0.67), "Средний", "Высокий")) -> Низкий
A10: Курская область | B10: Kursk Oblast | C10: КУР | D10: 8 | E10: 20 | F10: =SUMIF(population_edit!A$2:A$1276, A10, population_edit!C$2:C$1276) -> 87470 | G10: =SUMIF(population_edit!A$2:A$1274, A10, population_edit!D$2:D$1276) -> 82886 | H10: =(D10/F10)*100000 -> 9.1459929 | I10: =(E10/G10)*100000 -> 24.129527 | J10: =IFERROR( (D10 + E10) / (F10 + G10) * 100000, "" ) -> 16.436169 | K10: =IF(J10 <= PERCENTILE(J$2:J$86, 0.33), "Низкий", IF(J10 <= PERCENTILE(J$2:J$86, 0.67), "Средний", "Высокий")) -> Высокий
A11: Липецкая область | B11: Lipetsk Oblast | C11: ЛИП | D11: 13 | E11: 6 | F11: =SUMIF(population_edit!A$2:A$1276, A11, population_edit!C$2:C$1276) -> 91417 | G11: =SUMIF(population_edit!A$2:A$1274, A11, population_edit!D$2:D$1276) -> 86872 | H11: =(D11/F11)*100000 -> 14.22055 | I11: =(E11/G11)*100000 -> 6.9067133 | J11: =IFERROR( (D11 + E11) / (F11 + G11) * 100000, "" ) -> 10.656855 | K11: =IF(J11 <= PERCENTILE(J$2:J$86, 0.33), "Низкий", IF(J11 <= PERCENTILE(J$2:J$86, 0.67), "Средний", "Высокий")) -> Средний
A12: г. Москва | B12: Moscow | C12: МСК | D12: 99 | E12: 93 | F12: =SUMIF(population_edit!A$2:A$1276, A12, population_edit!C$2:C$1276) -> 1016163 | G12: =SUMIF(population_edit!A$2:A$1274, A12, population_edit!D$2:D$1276) -> 950645 | H12: =(D12/F12)*100000 -> 9.7425315 | I12: =(E12/G12)*100000 -> 9.7828317 | J12: =IFERROR( (D12 + E12) / (F12 + G12) * 100000, "" ) -> 9.7620103 | K12: =IF(J12 <= PERCENTILE(J$2:J$86, 0.33), "Низкий", IF(J12 <= PERCENTILE(J$2:J$86, 0.67), "Средний", "Высокий")) -> Низкий
A13: Московская область | B13: Moscow region | C13: МО | D13: 71 | E13: 59 | F13: =SUMIF(population_edit!A$2:A$1276, A13, population_edit!C$2:C$1276) -> 788643 | G13: =SUMIF(population_edit!A$2:A$1274, A13, population_edit!D$2:D$1276) -> 716596 | H13: =(D13/F13)*100000 -> 9.0028061 | I13: =(E13/G13)*100000 -> 8.23337 | J13: =IFERROR( (D13 + E13) / (F13 + G13) * 100000, "" ) -> 8.6365022 | K13: =IF(J13 <= PERCENTILE(J$2:J$86, 0.33), "Низкий", IF(J13 <= PERCENTILE(J$2:J$86, 0.67), "Средний", "Высокий")) -> Низкий
... A86: Еврейская АО | B86: Chukotka Autonomous Okrug | C86: ЧУК | D86: 3 | E86: 0 | F86: =SUMIF(population_edit!A$2:A$1276, A86, population_edit!C$2:C$1276) -> 14297 | G86: =SUMIF(population_edit!A$2:A$1274, A86, population_edit!D$2:D$1276) -> 13553 | H86: =(D86/F86)*100000 -> 20.983423 | I86: =(E86/G86)*100000 -> 0 | J86: =IFERROR( (D86 + E86) / (F86 + G86) * 100000, "" ) -> 10.771993 | K86: =IF(J86 <= PERCENTILE(J$2:J$86, 0.33), "Низкий", IF(J86 <= PERCENTILE(J$2:J$86, 0.67), "Средний", "Высокий")) -> Средний

Sheet top-10_cancer_by_region

Sheet cancer_by_region_meta
A1: Источник: ЗЛОКАЧЕСТВЕНЕННЫЕ НОВООБРАЗОВАНИЯ В РОССИИ В 2022 ГОДУ Таблица 116, стр. 252-253
A2: region | B2: регион
A3: male_abs_num | B3: абсолютное число впервые заболевших среди мальчиков
A4: female_abs_num | B4: абсолютное число впервые заболевших среди девочек
A5: male_population_0-14 | B5: численность мальчиков в возрасте 0-14
A6: female_population_0-14 | B6: численность девочек в возрасте 0-14
A7: male_per_100k | B7: показатель заболеваемости среди мальчиков на 100 тыс. населения мальчиков в возрасте 0-14
A8: female_per_100k | B8: показатель заболеваемости среди девочек на 100 тыс. населения девочек в возрасте 0-14
A9: total_death_risk_group | B9: Категория уровня онкозаболеваемости в регионе на основе показателя общей онкозаболеваемости на 100 тыс. детей 0-14 лет. Метод формирования: регионы распределены по трем группам с использованием 33-го и 67-го процентилей распределения показателя total_death_rate_per100k. Значения: 1) низкий — регионы, в которых значение показателя ниже 33-го процентиля (наименьшие уровни заболеваемости); 2) средний — регионы со значением между 33-м и 67-м процентилями; 3) высокий — регионы со значением выше 67-го процентиля (наибольшие уровни заболеваемости).
A10: Пояснения: Нулевые значения в датасете означают отсутствие зарегистрированных случаев заболевания. Поэтому я не стала их удалять.

Sheet cancer_by_type_edit
A1: localization | B1: male_abs_num_0-14 | C1: female_abs_num_0-14 | D1: male_share% | E1: female_share% | F1: male_rate_per100k | G1: female_rate_per100k | H1: rate_ratio_by_male
A2: Большие слюнные железы | B2: 2 | C2: 3 | D2: =B2 / SUM(B:B) -> 0.0013850416 | E2: =C2 / SUM(C:C) -> 0.0025252525 | F2: =B2 / SUM(population_edit!C2:C1276) * 100000 -> 0.015223803 | G2: =C2 / SUM(population_edit!D25:D1299) * 100000 -> 0.024498157 | H2: =IFERROR(F2/G2, "Нет данных") -> 0.62142645
A3: Другие и неуточненные части полости рта | B3: 1 | C3: 2 | D3: =B3 / SUM(B:B) -> 0.00069252078 | E3: =C3 / SUM(C:C) -> 0.0016835017 | F3: =B3 / SUM(population_edit!C3:C1277) * 100000 -> 0.0076150733 | G3: =C3 / SUM(population_edit!D26:D1300) * 100000 -> 0.016340604 | H3: =IFERROR(F3/G3, "Нет данных") -> 0.46602154
A4: Ротоглотка | B4: 0 | C4: 0 | D4: =B4 / SUM(B:B) -> 0 | E4: =C4 / SUM(C:C) -> 0 | F4: =B4 / SUM(population_edit!C4:C1278) * 100000 -> 0 | G4: =C4 / SUM(population_edit!D27:D1301) * 100000 -> 0 | H4: =IFERROR(F4/G4, "Нет данных") -> Нет данных
A5: Носоглотка | B5: 3 | C5: 3 | D5: =B5 / SUM(B:B) -> 0.0020775623 | E5: =C5 / SUM(C:C) -> 0.0025252525 | F5: =B5 / SUM(population_edit!C5:C1279) * 100000 -> 0.022866966 | G5: =C5 / SUM(population_edit!D28:D1302) * 100000 -> 0.024538057 | H5: =IFERROR(F5/G5, "Нет данных") -> 0.93189798
A6: Печень и внутрипеч. желчные протоки | B6: 25 | C6: 19 | D6: =B6 / SUM(B:B) -> 0.017313019 | E6: =C6 / SUM(C:C) -> 0.015993266 | F6: =B6 / SUM(population_edit!C6:C1280) * 100000 -> 0.19065831 | G6: =C6 / SUM(population_edit!D29:D1303) * 100000 -> 0.15549096 | H6: =IFERROR(F6/G6, "Нет данных") -> 1.2261697
A7: Полость носа, среднее ухо, придаточные пазухи | B7: 3 | C7: 2 | D7: =B7 / SUM(B:B) -> 0.0020775623 | E7: =C7 / SUM(C:C) -> 0.0016835017 | F7: =B7 / SUM(population_edit!C7:C1281) * 100000 -> 0.02289183 | G7: =C7 / SUM(population_edit!D30:D1304) * 100000 -> 0.016376276 | H7: =IFERROR(F7/G7, "Нет данных") -> 1.3978655
A8: Кости и суставные хрящи | B8: 77 | C8: 75 | D8: =B8 / SUM(B:B) -> 0.0533241 | E8: =C8 / SUM(C:C) -> 0.063131313 | F8: =B8 / SUM(population_edit!C8:C1282) * 100000 -> 0.58790995 | G8: =C8 / SUM(population_edit!D31:D1305) * 100000 -> 0.61444234 | H8: =IFERROR(F8/G8, "Нет данных") -> 0.95681873
A9: Меланома кожи | B9: 0 | C9: 4 | D9: =B9 / SUM(B:B) -> 0 | E9: =C9 / SUM(C:C) -> 0.0033670034 | F9: =B9 / SUM(population_edit!C9:C1283) * 100000 -> 0 | G9: =C9 / SUM(population_edit!D32:D1306) * 100000 -> 0.03278864 | H9: =IFERROR(F9/G9, "Нет данных") -> 0
A10: Соединительная и другие мягкие ткани | B10: 86 | C10: 80 | D10: =B10 / SUM(B:B) -> 0.059556787 | E10: =C10 / SUM(C:C) -> 0.067340067 | F10: =B10 / SUM(population_edit!C10:C1284) * 100000 -> 0.65753267 | G10: =C10 / SUM(population_edit!D33:D1307) * 100000 -> 0.65599946 | H10: =IFERROR(F10/G10, "Нет данных") -> 1.0023372
A11: Яичник | B11: 0 | C11: 40 | D11: =B11 / SUM(B:B) -> 0 | E11: =C11 / SUM(C:C) -> 0.033670034 | F11: =B11 / SUM(population_edit!C11:C1285) * 100000 -> 0 | G11: =C11 / SUM(population_edit!D34:D1308) * 100000 -> 0.32812675 | H11: =IFERROR(F11/G11, "Нет данных") -> 0
A12: Яичко | B12: 15 | C12: 0 | D12: =B12 / SUM(B:B) -> 0.010387812 | E12: =C12 / SUM(C:C) -> 0 | F12: =B12 / SUM(population_edit!C12:C1286) * 100000 -> 0.11484924 | G12: =C12 / SUM(population_edit!D35:D1309) * 100000 -> 0 | H12: =IFERROR(F12/G12, "Нет данных") -> Нет данных
A13: Почка | B13: 92 | C13: 92 | D13: =B13 / SUM(B:B) -> 0.063711911 | E13: =C13 / SUM(C:C) -> 0.077441077 | F13: =B13 / SUM(population_edit!C13:C1287) * 100000 -> 0.70491591 | G13: =C13 / SUM(population_edit!D36:D1310) * 100000 -> 0.75531783 | H13: =IFERROR(F13/G13, "Нет данных") -> 0.93327059
... A27: Другие неуточненные ЗНО лимфатической и кроветворной ткани | B27: 16 | C27: 13 | D27: =B27 / SUM(B:B) -> 0.011080332 | E27: =C27 / SUM(C:C) -> 0.010942761 | F27: =B27 / SUM(population_edit!C27:C1301) * 100000 -> 0.12348773 | G27: =C27 / SUM(population_edit!D50:D1324) * 100000 -> 0.10765986 | H27: =IFERROR(F27/G27, "Нет данных") -> 1.1470174

Sheet top10localizations_cancer_by_ty

Sheet cancer_by_type_meta
A1: Источник: ЗЛОКАЧЕСТВЕНЕННЫЕ НОВООБРАЗОВАНИЯ В РОССИИ В 2022 ГОДУ Таблица 115, стр. 250-251
A2: localization | B2: локализация заболевания
A3: male_abs_num_0-14 | B3: абсолютное число впервые заболевших среди мужского пола в возрасте 0-14 лет
A4: female_abs_num_0-14 | B4: абсолютное число впервые заболевших среди женского пола в возрасте 0-14 лет
A5: male_share% | B5: доля (в процентах) от всех заболевших мальчиков, которая приходится на данный вид ЗНО (для сравнения структуры заболеваемости)
A6: female_share% | B6: доля (в процентах) от всех заболевших девочек, которая приходится на данный вид ЗНО (для сравнения структуры заболеваемости)
A7: male_rate_per100k | B7: сколько случаев данного вида ЗНО приходится на 100 000 мальчиков (в возрасте 0–14 лет)
A8: female_rate_per100k | B8: сколько случаев данного вида ЗНО приходится на 100 000 девочек (в возрасте 0–14 лет)
A9: rate_ratio_by_male | B9: во сколько раз заболеваемость мальчиков выше (или ниже) заболеваемости девочек/ rate_ratio = 1 → заболеваемость одинакова у мальчиков и девочек. rate_ratio > 1 → мальчики болеют чаще. Например, 2,5 означает, что у мальчиков заболеваемость в 2,5 раза выше. rate_ratio < 1 → девочки болеют чаще. Например, 0,4 означает, что у девочек заболеваемость в 2,5 раза выше (поскольку 1 / 0,4 = 2,5).
A10: Пояснения: Нулевые значения в датасете означают отсутствие зарегистрированных случаев заболевания. Поэтому я не стала их удалять.

Sheet cancer_by_age_type_edit
A1: localization | B1: abs_num_0-4 | C1: abs_num_5-9 | D1: abs_num_10-14 | E1: rate_0-4_per100k | F1: rate_5-9_per100k | G1: rate_10-14_per100k | H1: outliers_0-4 | I1: outliers_5-9 | J1: outliers_10-14 | M1: показатель | N1: 0-4 | O1: 46270 | P1: 10-14
A2: Губа | B2: 0 | C2: 0 | D2: 0 | E2: =B2 / (population_dop_znach!B$2 + population_dop_znach!C$2) * 100000 -> 0 | F2: =C2/ (population_dop_znach!B$3 + population_dop_znach!C$3) * 100000 -> 0 | G2: =D2 / (population_dop_znach!B$4 + population_dop_znach!C$4) * 100000 -> 0 | H2: =IF(E2 > $N$2, "Выброс", "Нет") -> Нет | I2: =IF(F2 > $O$2, "Выброс", "Нет") -> Нет | J2: =IF(F2 > $P$2, "Выброс", "Нет") -> Нет | M2: 95-й персентиль | N2: =PERCENTILE(E1:E1002, 0.95) -> 1.6580256 | O2: =PERCENTILE(F1:F1002, 0.95) -> 0.79641372 | P2: =PERCENTILE(G1:G1002, 0.95) -> 1.0432208
A3: Язык | B3: 0 | C3: 0 | D3: 0 | E3: =B3 / (population_dop_znach!B$2 + population_dop_znach!C$2) * 100000 -> 0 | F3: =C3/ (population_dop_znach!B$3 + population_dop_znach!C$3) * 100000 -> 0 | G3: =D3 / (population_dop_znach!B$4 + population_dop_znach!C$4) * 100000 -> 0 | H3: =IF(E3 > $N$2, "Выброс", "Нет") -> Нет | I3: =IF(F3 > $O$2, "Выброс", "Нет") -> Нет | J3: =IF(F3 > $P$2, "Выброс", "Нет") -> Нет
A4: Большие слюнные железы | B4: 1 | C4: 1 | D4: 3 | E4: =B4 / (population_dop_znach!B$2 + population_dop_znach!C$2) * 100000 -> 0.013897952 | F4: =C4/ (population_dop_znach!B$3 + population_dop_znach!C$3) * 100000 -> 0.010668637 | G4: =D4 / (population_dop_znach!B$4 + population_dop_znach!C$4) * 100000 -> 0.033436563 | H4: =IF(E4 > $N$2, "Выброс", "Нет") -> Нет | I4: =IF(F4 > $O$2, "Выброс", "Нет") -> Нет | J4: =IF(F4 > $P$2, "Выброс", "Нет") -> Нет
A5: Другие и неуточненные части полости рта | B5: 1 | C5: 0 | D5: 2 | E5: =B5 / (population_dop_znach!B$2 + population_dop_znach!C$2) * 100000 -> 0.013897952 | F5: =C5/ (population_dop_znach!B$3 + population_dop_znach!C$3) * 100000 -> 0 | G5: =D5 / (population_dop_znach!B$4 + population_dop_znach!C$4) * 100000 -> 0.022291042 | H5: =IF(E5 > $N$2, "Выброс", "Нет") -> Нет | I5: =IF(F5 > $O$2, "Выброс", "Нет") -> Нет | J5: =IF(F5 > $P$2, "Выброс", "Нет") -> Нет
A6: Ротоглотка | B6: 0 | C6: 0 | D6: 0 | E6: =B6 / (population_dop_znach!B$2 + population_dop_znach!C$2) * 100000 -> 0 | F6: =C6/ (population_dop_znach!B$3 + population_dop_znach!C$3) * 100000 -> 0 | G6: =D6 / (population_dop_znach!B$4 + population_dop_znach!C$4) * 100000 -> 0 | H6: =IF(E6 > $N$2, "Выброс", "Нет") -> Нет | I6: =IF(F6 > $O$2, "Выброс", "Нет") -> Нет | J6: =IF(F6 > $P$2, "Выброс", "Нет") -> Нет
A7: Носоглотка | B7: 0 | C7: 2 | D7: 4 | E7: =B7 / (population_dop_znach!B$2 + population_dop_znach!C$2) * 100000 -> 0 | F7: =C7/ (population_dop_znach!B$3 + population_dop_znach!C$3) * 100000 -> 0.021337273 | G7: =D7 / (population_dop_znach!B$4 + population_dop_znach!C$4) * 100000 -> 0.044582084 | H7: =IF(E7 > $N$2, "Выброс", "Нет") -> Нет | I7: =IF(F7 > $O$2, "Выброс", "Нет") -> Нет | J7: =IF(F7 > $P$2, "Выброс", "Нет") -> Нет
A8: Гортаноглотка | B8: 0 | C8: 0 | D8: 0 | E8: =B8 / (population_dop_znach!B$2 + population_dop_znach!C$2) * 100000 -> 0 | F8: =C8/ (population_dop_znach!B$3 + population_dop_znach!C$3) * 100000 -> 0 | G8: =D8 / (population_dop_znach!B$4 + population_dop_znach!C$4) * 100000 -> 0 | H8: =IF(E8 > $N$2, "Выброс", "Нет") -> Нет | I8: =IF(F8 > $O$2, "Выброс", "Нет") -> Нет | J8: =IF(F8 > $P$2, "Выброс", "Нет") -> Нет
A9: Пищевод | B9: 0 | C9: 0 | D9: 0 | E9: =B9 / (population_dop_znach!B$2 + population_dop_znach!C$2) * 100000 -> 0 | F9: =C9/ (population_dop_znach!B$3 + population_dop_znach!C$3) * 100000 -> 0 | G9: =D9 / (population_dop_znach!B$4 + population_dop_znach!C$4) * 100000 -> 0 | H9: =IF(E9 > $N$2, "Выброс", "Нет") -> Нет | I9: =IF(F9 > $O$2, "Выброс", "Нет") -> Нет | J9: =IF(F9 > $P$2, "Выброс", "Нет") -> Нет
A10: Желудок | B10: 0 | C10: 0 | D10: 2 | E10: =B10 / (population_dop_znach!B$2 + population_dop_znach!C$2) * 100000 -> 0 | F10: =C10/ (population_dop_znach!B$3 + population_dop_znach!C$3) * 100000 -> 0 | G10: =D10 / (population_dop_znach!B$4 + population_dop_znach!C$4) * 100000 -> 0.022291042 | H10: =IF(E10 > $N$2, "Выброс", "Нет") -> Нет | I10: =IF(F10 > $O$2, "Выброс", "Нет") -> Нет | J10: =IF(F10 > $P$2, "Выброс", "Нет") -> Нет
A11: Тонкий кишечник | B11: 0 | C11: 0 | D11: 1 | E11: =B11 / (population_dop_znach!B$2 + population_dop_znach!C$2) * 100000 -> 0 | F11: =C11/ (population_dop_znach!B$3 + population_dop_znach!C$3) * 100000 -> 0 | G11: =D11 / (population_dop_znach!B$4 + population_dop_znach!C$4) * 100000 -> 0.011145521 | H11: =IF(E11 > $N$2, "Выброс", "Нет") -> Нет | I11: =IF(F11 > $O$2, "Выброс", "Нет") -> Нет | J11: =IF(F11 > $P$2, "Выброс", "Нет") -> Нет
A12: Ободочная кишка | B12: 1 | C12: 2 | D12: 14 | E12: =B12 / (population_dop_znach!B$2 + population_dop_znach!C$2) * 100000 -> 0.013897952 | F12: =C12/ (population_dop_znach!B$3 + population_dop_znach!C$3) * 100000 -> 0.021337273 | G12: =D12 / (population_dop_znach!B$4 + population_dop_znach!C$4) * 100000 -> 0.15603729 | H12: =IF(E12 > $N$2, "Выброс", "Нет") -> Нет | I12: =IF(F12 > $O$2, "Выброс", "Нет") -> Нет | J12: =IF(F12 > $P$2, "Выброс", "Нет") -> Нет
A13: Прямая кишка, ректосиг. соединение, анус | B13: 0 | C13: 0 | D13: 1 | E13: =B13 / (population_dop_znach!B$2 + population_dop_znach!C$2) * 100000 -> 0 | F13: =C13/ (population_dop_znach!B$3 + population_dop_znach!C$3) * 100000 -> 0 | G13: =D13 / (population_dop_znach!B$4 + population_dop_znach!C$4) * 100000 -> 0.011145521 | H13: =IF(E13 > $N$2, "Выброс", "Нет") -> Нет | I13: =IF(F13 > $O$2, "Выброс", "Нет") -> Нет | J13: =IF(F13 > $P$2, "Выброс", "Нет") -> Нет
A14: Печень и внутрипеч. желчные протоки | B14: 29 | C14: 10 | D14: 5 | E14: =B14 / (population_dop_znach!B$2 + population_dop_znach!C$2) * 100000 -> 0.40304059 | F14: =C14/ (population_dop_znach!B$3 + population_dop_znach!C$3) * 100000 -> 0.10668637 | G14: =D14 / (population_dop_znach!B$4 + population_dop_znach!C$4) * 100000 -> 0.055727605 | H14: =IF(E14 > $N$2, "Выброс", "Нет") -> Нет | I14: =IF(F14 > $O$2, "Выброс", "Нет") -> Нет | J14: =IF(F14 > $P$2, "Выброс", "Нет") -> Нет
... A49: Другие неуточненные ЗНО лимфатической и кроветворной ткани | B49: 2 | C49: 7 | D49: 3 | E49: =B49 / (population_dop_znach!B$2 + population_dop_znach!C$2) * 100000 -> 0.027795903 | F49: =C49/ (population_dop_znach!B$3 + population_dop_znach!C$3) * 100000 -> 0.074680456 | G49: =D49 / (population_dop_znach!B$4 + population_dop_znach!C$4) * 100000 -> 0.033436563 | H49: =IF(E49 > $N$2, "Выброс", "Нет") -> Нет | I49: =IF(F49 > $O$2, "Выброс", "Нет") -> Нет | J49: =IF(F49 > $P$2, "Выброс", "Нет") -> Нет

Sheet outliers_cancer_by_age_type
A1: localization | B1: SUM из rate_0-4_per100k
A2: Головной мозг | B2: 1.8623255
A3: Острый лимфолейкоз | B3: 5.3090175
A4: Почка | B4: 1.9318153
A6: localization | B6: SUM из rate_5-9_per100k
A7: Головной мозг | B7: 1.6536387
A8: Неходжкинская лимфома, другие ЗНО лимоидной ткани | B8: 0.94950865
A9: Острый лимфолейкоз | B9: 3.1045732

Sheet cancer_by_age_type_meta
A1: "Источник: ЗЛОКАЧЕСТВЕНЕННЫЕ НОВООБРАЗОВАНИЯ В РОССИИ В 2022 ГОДУ Таблица 9, стр. 31-35
A2: localization | B2: локализация заболевания
A3: abs_num_0-4 | B3: абсолютное число случаев в возрастной группе 0–4 года
A4: abs_num_5-9 | B4: абсолютное число случаев в возрастной группе 5–9 лет
A5: abs_num_10-14 | B5: абсолютное число случаев в возрастной группе 10–14 лет
A6: rate_0-4_per100k | B6: показатель заболеваемости в возрастной группе 0–4 года, рассчитанный на 100 тыс. детей этого возраста
A7: rate_5-9_per100k | B7: показатель заболеваемости в возрастной группе 5–9 лет, рассчитанный на 100 тыс. детей этого возраста
A8: rate_10-14_per100k | B8: показатель заболеваемости в возрастной группе 10–14 лет, рассчитанный на 100 тыс. детей этого возраста
A9: outliers_0-4 | B9: «выброс» — локализация с показателем выше 95-го процентиля (аномально высокая заболеваемость) в возрасте 0-4 года.
A10: outliers_5-9 | B10: «выброс» — локализация с показателем выше 95-го процентиля (аномально высокая заболеваемость) в возрасте 5-9 лет.
A11: outliers_10-14 | B11: «выброс» — локализация с показателем выше 95-го процентиля (аномально высокая заболеваемость) в возрасте 10-14 лет.
A12: Пояснения: Нулевые значения в датасете означают отсутствие зарегистрированных случаев заболевания. Поэтому я не стала их удалять.

Sheet death_cancer_by_region_edit
A1: region | B1: region_english | C1: squares code | D1: male_death_abs_num | E1: female_death_abs_num | F1: male_death_rate_per100k | G1: female_death_rate_per100k | H1: total_death_rate_per100k | I1: total_death_risk_group
A2: Белгородская область | B2: Belgorod Oblast | C2: БЕЛ | D2: 9 | E2: 2 | F2: =IFERROR(D2 / SUMIF(population_edit!A$2:A$1276, A2, population_edit!C$2:C$1276) * 100000, 0) -> 7.4136312 | G2: =IFERROR(E2 / SUMIF(population_edit!A$2:A$1276, A2, population_edit!D$2:D$1276) * 100000, 0) -> 1.7425549 | H2: =IFERROR((D2+E2) / (SUMIF(population_edit!A$2:A$1276, A2, population_edit!C$2:C$1276) + SUMIF(population_edit!A$2:A$1276, A2, population_edit!D$2:D$1276)) * 100000, 0) -> 4.6576224 | I2: =IF(H2 <= PERCENTILE(H$2:H$86, 0.33), "Низкий", IF(H2 <= PERCENTILE(H$2:H$86, 0.67), "Средний", "Высокий")) -> Высокий
A3: Брянская область | B3: Bryansk Oblast | C3: БРЯ | D3: 2 | E3: 1 | F3: =IFERROR(D3 / SUMIF(population_edit!A$2:A$1276, A3, population_edit!C$2:C$1276) * 100000, 0) -> 2.1240893 | G3: =IFERROR(E3 / SUMIF(population_edit!A$2:A$1276, A3, population_edit!D$2:D$1276) * 100000, 0) -> 1.1192568 | H3: =IFERROR((D3+E3) / (SUMIF(population_edit!A$2:A$1276, A3, population_edit!C$2:C$1276) + SUMIF(population_edit!A$2:A$1276, A3, population_edit!D$2:D$1276)) * 100000, 0) -> 1.6348507 | I3: =IF(H3 <= PERCENTILE(H$2:H$86, 0.33), "Низкий", IF(H3 <= PERCENTILE(H$2:H$86, 0.67), "Средний", "Высокий")) -> Низкий
A4: Владимирская область | B4: Vladimir Oblast | C4: ВЛД | D4: 4 | E4: 1 | F4: =IFERROR(D4 / SUMIF(population_edit!A$2:A$1276, A4, population_edit!C$2:C$1276) * 100000, 0) -> 3.8667517 | G4: =IFERROR(E4 / SUMIF(population_edit!A$2:A$1276, A4, population_edit!D$2:D$1276) * 100000, 0) -> 1.0242019 | H4: =IFERROR((D4+E4) / (SUMIF(population_edit!A$2:A$1276, A4, population_edit!C$2:C$1276) + SUMIF(population_edit!A$2:A$1276, A4, population_edit!D$2:D$1276)) * 100000, 0) -> 2.4865354 | I4: =IF(H4 <= PERCENTILE(H$2:H$86, 0.33), "Низкий", IF(H4 <= PERCENTILE(H$2:H$86, 0.67), "Средний", "Высокий")) -> Средний
A5: Воронежская область | B5: Voronezh Oblast | C5: ВРЖ | D5: 4 | E5: 3 | F5: =IFERROR(D5 / SUMIF(population_edit!A$2:A$1276, A5, population_edit!C$2:C$1276) * 100000, 0) -> 2.260053 | G5: =IFERROR(E5 / SUMIF(population_edit!A$2:A$1276, A5, population_edit!D$2:D$1276) * 100000, 0) -> 1.7908416 | H5: =IFERROR((D5+E5) / (SUMIF(population_edit!A$2:A$1276, A5, population_edit!C$2:C$1276) + SUMIF(population_edit!A$2:A$1276, A5, population_edit!D$2:D$1276)) * 100000, 0) -> 2.0318949 | I5: =IF(H5 <= PERCENTILE(H$2:H$86, 0.33), "Низкий", IF(H5 <= PERCENTILE(H$2:H$86, 0.67), "Средний", "Высокий")) -> Средний
A6: Ивановская область | B6: Ivanovo Oblast | C6: ИВА | D6: 1 | E6: 2 | F6: =IFERROR(D6 / SUMIF(population_edit!A$2:A$1276, A6, population_edit!C$2:C$1276) * 100000, 0) -> 1.3984449 | G6: =IFERROR(E6 / SUMIF(population_edit!A$2:A$1276, A6, population_edit!D$2:D$1276) * 100000, 0) -> 3.0147724 | H6: =IFERROR((D6+E6) / (SUMIF(population_edit!A$2:A$1276, A6, population_edit!C$2:C$1276) + SUMIF(population_edit!A$2:A$1276, A6, population_edit!D$2:D$1276)) * 100000, 0) -> 2.1763101 | I6: =IF(H6 <= PERCENTILE(H$2:H$86, 0.33), "Низкий", IF(H6 <= PERCENTILE(H$2:H$86, 0.67), "Средний", "Высокий")) -> Средний
A7: Тверская область | B7: Tver Oblast | C7: ТВР | D7: 3 | E7: 3 | F7: =IFERROR(D7 / SUMIF(population_edit!A$2:A$1276, A7, population_edit!C$2:C$1276) * 100000, 0) -> 3.1209687 | G7: =IFERROR(E7 / SUMIF(population_edit!A$2:A$1276, A7, population_edit!D$2:D$1276) * 100000, 0) -> 3.2598066 | H7: =IFERROR((D7+E7) / (SUMIF(population_edit!A$2:A$1276, A7, population_edit!C$2:C$1276) + SUMIF(population_edit!A$2:A$1276, A7, population_edit!D$2:D$1276)) * 100000, 0) -> 3.1888772 | I7: =IF(H7 <= PERCENTILE(H$2:H$86, 0.33), "Низкий", IF(H7 <= PERCENTILE(H$2:H$86, 0.67), "Средний", "Высокий")) -> Высокий
A8: Калужская область | B8: Kaluga Oblast | C8: КЛУ | D8: 1 | E8: 4 | F8: =IFERROR(D8 / SUMIF(population_edit!A$2:A$1276, A8, population_edit!C$2:C$1276) * 100000, 0) -> 1.1546944 | G8: =IFERROR(E8 / SUMIF(population_edit!A$2:A$1276, A8, population_edit!D$2:D$1276) * 100000, 0) -> 4.8465462 | H8: =IFERROR((D8+E8) / (SUMIF(population_edit!A$2:A$1276, A8, population_edit!C$2:C$1276) + SUMIF(population_edit!A$2:A$1276, A8, population_edit!D$2:D$1276)) * 100000, 0) -> 2.9562009 | I8: =IF(H8 <= PERCENTILE(H$2:H$86, 0.33), "Низкий", IF(H8 <= PERCENTILE(H$2:H$86, 0.67), "Средний", "Высокий")) -> Высокий
A9: Костромская область | B9: Kostroma Oblast | C9: КОС | D9: 1 | E9: 1 | F9: =IFERROR(D9 / SUMIF(population_edit!A$2:A$1276, A9, population_edit!C$2:C$1276) * 100000, 0) -> 1.9662977 | G9: =IFERROR(E9 / SUMIF(population_edit!A$2:A$1276, A9, population_edit!D$2:D$1276) * 100000, 0) -> 2.0583755 | H9: =IFERROR((D9+E9) / (SUMIF(population_edit!A$2:A$1276, A9, population_edit!C$2:C$1276) + SUMIF(population_edit!A$2:A$1276, A9, population_edit!D$2:D$1276)) * 100000, 0) -> 2.0112833 | I9: =IF(H9 <= PERCENTILE(H$2:H$86, 0.33), "Низкий", IF(H9 <= PERCENTILE(H$2:H$86, 0.67), "Средний", "Высокий")) -> Средний
A10: Курская область | B10: Kursk Oblast | C10: КУР | D10: 2 | E10: 2 | F10: =IFERROR(D10 / SUMIF(population_edit!A$2:A$1276, A10, population_edit!C$2:C$1276) * 100000, 0) -> 2.2864982 | G10: =IFERROR(E10 / SUMIF(population_edit!A$2:A$1276, A10, population_edit!D$2:D$1276) * 100000, 0) -> 2.4129527 | H10: =IFERROR((D10+E10) / (SUMIF(population_edit!A$2:A$1276, A10, population_edit!C$2:C$1276) + SUMIF(population_edit!A$2:A$1276, A10, population_edit!D$2:D$1276)) * 100000, 0) -> 2.3480241 | I10: =IF(H10 <= PERCENTILE(H$2:H$86, 0.33), "Низкий", IF(H10 <= PERCENTILE(H$2:H$86, 0.67), "Средний", "Высокий")) -> Средний
A11: Липецкая область | B11: Lipetsk Oblast | C11: ЛИП | D11: 1 | E11: 1 | F11: =IFERROR(D11 / SUMIF(population_edit!A$2:A$1276, A11, population_edit!C$2:C$1276) * 100000, 0) -> 1.0938884 | G11: =IFERROR(E11 / SUMIF(population_edit!A$2:A$1276, A11, population_edit!D$2:D$1276) * 100000, 0) -> 1.1511189 | H11: =IFERROR((D11+E11) / (SUMIF(population_edit!A$2:A$1276, A11, population_edit!C$2:C$1276) + SUMIF(population_edit!A$2:A$1276, A11, population_edit!D$2:D$1276)) * 100000, 0) -> 1.1217742 | I11: =IF(H11 <= PERCENTILE(H$2:H$86, 0.33), "Низкий", IF(H11 <= PERCENTILE(H$2:H$86, 0.67), "Средний", "Высокий")) -> Низкий
A12: г. Москва | B12: Moscow | C12: МСК | D12: 67 | E12: 54 | F12: =IFERROR(D12 / SUMIF(population_edit!A$2:A$1276, A12, population_edit!C$2:C$1276) * 100000, 0) -> 6.5934304 | G12: =IFERROR(E12 / SUMIF(population_edit!A$2:A$1276, A12, population_edit!D$2:D$1276) * 100000, 0) -> 5.6803539 | H12: =IFERROR((D12+E12) / (SUMIF(population_edit!A$2:A$1276, A12, population_edit!C$2:C$1276) + SUMIF(population_edit!A$2:A$1276, A12, population_edit!D$2:D$1276)) * 100000, 0) -> 6.1521003 | I12: =IF(H12 <= PERCENTILE(H$2:H$86, 0.33), "Низкий", IF(H12 <= PERCENTILE(H$2:H$86, 0.67), "Средний", "Высокий")) -> Высокий
A13: Московская область | B13: Moscow region | C13: МО | D13: 20 | E13: 14 | F13: =IFERROR(D13 / SUMIF(population_edit!A$2:A$1276, A13, population_edit!C$2:C$1276) * 100000, 0) -> 2.5360017 | G13: =IFERROR(E13 / SUMIF(population_edit!A$2:A$1276, A13, population_edit!D$2:D$1276) * 100000, 0) -> 1.953681 | H13: =IFERROR((D13+E13) / (SUMIF(population_edit!A$2:A$1276, A13, population_edit!C$2:C$1276) + SUMIF(population_edit!A$2:A$1276, A13, population_edit!D$2:D$1276)) * 100000, 0) -> 2.2587775 | I13: =IF(H13 <= PERCENTILE(H$2:H$86, 0.33), "Низкий", IF(H13 <= PERCENTILE(H$2:H$86, 0.67), "Средний", "Высокий")) -> Средний
... A86: Еврейская АО | B86: Chukotka Autonomous Okrug | C86: ЧУК | D86: 0 | E86: 0 | F86: =IFERROR(D86 / SUMIF(population_edit!A$2:A$1276, A86, population_edit!C$2:C$1276) * 100000, 0) -> 0 | G86: =IFERROR(E86 / SUMIF(population_edit!A$2:A$1276, A86, population_edit!D$2:D$1276) * 100000, 0) -> 0 | H86: =IFERROR((D86+E86) / (SUMIF(population_edit!A$2:A$1276, A86, population_edit!C$2:C$1276) + SUMIF(population_edit!A$2:A$1276, A86, population_edit!D$2:D$1276)) * 100000, 0) -> 0 | I86: =IF(H86 <= PERCENTILE(H$2:H$86, 0.33), "Низкий", IF(H86 <= PERCENTILE(H$2:H$86, 0.67), "Средний", "Высокий")) -> Низкий

Sheet antitop-10_death_cancer_by_regi
C1: Антитоп по общей смертности на 100 тыс. детей

Sheet death_cancer_by_region_meta
A1: Источник: ЗЛОКАЧЕСТВЕНЕННЫЕ НОВООБРАЗОВАНИЯ В РОССИИ В 2022 ГОДУ Таблица 123, стр. 263-264
A2: region | B2: регион
A3: male_death__abs_num | B3: абсолютное число случаев смерти среди мальчиков в возрасте 0-14
A4: female_death__abs_num | B4: абсолютное число случаев смерти среди девочек в возрасте 0-14
A5: male_death_rate_per100k | B5: Смертность среди мальчиков в регионе (на 100 тыс. мальчиков 0–14 лет)
A6: female_death_rate_per100k | B6: Смертность среди девочек в регионе (на 100 тыс. девочек 0–14 лет)
A7: total_death_rate_per100k | B7: Общая смертность в регионе (на 100 тыс. детей 0–14 лет)
A8: total_death_risk_group | B8: Категория уровня детской смертности от ЗНО в регионе на основе показателя общей смертности на 100 тыс. детей 0-14 лет. Метод формирования: регионы распределены по трем группам с использованием 33-го и 67-го процентилей распределения показателя total_death_rate_per100k. Значения: 1) низкий — регионы, в которых значение показателя ниже 33-го процентиля (наименьшие уровни смертности); 2) средний — регионы со значением между 33-м и 67-м процентилями; 3) высокий — регионы со значением выше 67-го процентиля (наибольшие уровни смертности).
A9: Пояснения: Нулевые значения в датасете означают отсутствие зарегистрированных случаев смерти. Поэтому я не стала их удалять.

Sheet population_edit
A1: region | B1: age | C1: male | D1: female
A2: Белгородская область | B2: до 1 | C2: 5472 | D2: 5279
A3: Белгородская область | B3: 1 | C3: 6247 | D3: 5906
A4: Белгородская область | B4: 2 | C4: 6241 | D4: 5985
A5: Белгородская область | B5: 3 | C5: 6899 | D5: 6217
A6: Белгородская область | B6: 4 | C6: 7351 | D6: 6931
A7: Белгородская область | B7: 5 | C7: 7868 | D7: 7230
A8: Белгородская область | B8: 6 | C8: 8846 | D8: 8464
A9: Белгородская область | B9: 7 | C9: 9200 | D9: 8623
A10: Белгородская область | B10: 8 | C10: 9186 | D10: 8943
A11: Белгородская область | B11: 9 | C11: 9412 | D11: 8816
A12: Белгородская область | B12: 10 | C12: 9398 | D12: 8850
A13: Белгородская область | B13: 11 | C13: 9060 | D13: 8458
... A17: Брянская область | B17: до 1 | C17: 4167 | D17: 4053
A18: Брянская область | B18: 1 | C18: 4744 | D18: 4337
A19: Брянская область | B19: 2 | C19: 5028 | D19: 4679
A20: Брянская область | B20: 3 | C20: 5206 | D20: 4979
A21: Брянская область | B21: 4 | C21: 5814 | D21: 5529
A22: Брянская область | B22: 5 | C22: 5999 | D22: 5745
A23: Брянская область | B23: 6 | C23: 6944 | D23: 6706
A24: Брянская область | B24: 7 | C24: 7467 | D24: 6845
A25: Брянская область | B25: 8 | C25: 6850 | D25: 6369
A26: Брянская область | B26: 9 | C26: 6952 | D26: 6580
A27: Брянская область | B27: 10 | C27: 7094 | D27: 6963
A28: Брянская область | B28: 11 | C28: 7033 | D28: 6547
A29: Брянская область | B29: 12 | C29: 6588 | D29: 6571
... A31: Брянская область | B31: 14 | C31: 7290 | D31: 6843
A32: Владимирская область | B32: до 1 | C32: 4520 | D32: 4215
A33: Владимирская область | B33: 1 | C33: 4971 | D33: 4721
A34: Владимирская область | B34: 2 | C34: 5192 | D34: 4737
A35: Владимирская область | B35: 3 | C35: 5600 | D35: 5371
A36: Владимирская область | B36: 4 | C36: 6335 | D36: 6198
A37: Владимирская область | B37: 5 | C37: 6659 | D37: 6366
A38: Владимирская область | B38: 6 | C38: 8008 | D38: 7355
A39: Владимирская область | B39: 7 | C39: 8084 | D39: 7689
A40: Владимирская область | B40: 8 | C40: 7775 | D40: 7380
A41: Владимирская область | B41: 9 | C41: 7836 | D41: 7322
A42: Владимирская область | B42: 10 | C42: 8204 | D42: 7710
A43: Владимирская область | B43: 11 | C43: 7723 | D43: 7346
A44: Владимирская область | B44: 12 | C44: 7428 | D44: 7136
...

Sheet population_dop_znach
A1: age | B1: male | C1: female
A2: 0–4 | B2: 3703931 | C2: 3491374
A3: 5–9 | B3: 4820359 | C3: 4552910
A4: 10–14 | B4: 4613032 | C4: 4359182

Sheet population_meta
A1: Источник: по данным Росстата Численность населения Российской Федерации по полу и возрасту на 1 января 2023 Ссылка на отдельную гугл-таблицу с данными
A2: region | B2: регион
A3: age | B3: возраст
A4: male | B4: мальчики
A5: female | B5: девочки
